<?xml version="1.0" ?>
<!-- =================================================================================== -->
<!-- |    This document was autogenerated by xacro from as_arm.xacro                   | -->
<!-- |    EDITING THIS FILE BY HAND IS NOT RECOMMENDED                                 | -->
<!-- =================================================================================== -->
<robot name="as_arm" xmlns:xacro="http://www.ros.org/wiki/xacro">
  <!-- Include materials -->
  <material name="Black">
    <color rgba="0.0 0.0 0.0 1.0"/>
  </material>
  <material name="Gray">
    <color rgba="0.5 0.5 0.5 1.0"/>
  </material>
  <material name="Red">
    <color rgba="0.8 0.0 0.0 1.0"/>
  </material>
  <material name="White">
    <color rgba="1.0 1.0 1.0 1.0"/>
  </material>
  <!-- Constants -->
  <!-- equal to PI/180-->
  <!-- Define materials mass -->
  <link name="world"/>
  <joint name="world_joint" type="fixed">
    <origin rpy="0 0 0" xyz="0 0 0.04"/>
    <parent link="world"/>
    <child link="base_link"/>
  </joint>
  <!-- ////  bottom link -> base link  ////-->
  <link name="bottom_link">
    <visual>
      <origin rpy="0 0 0" xyz="0 0 -0.03"/>
      <geometry>
        <box size="1 1 0.02"/>
      </geometry>
      <material name="White"/>
    </visual>
    <collision>
      <origin rpy="0 0 0" xyz=" 0 0 -0.03"/>
      <geometry>
        <box size="1 1 0.02"/>
      </geometry>
    </collision>
  </link>
  <gazebo reference="bottom_link">
    <material>Gazebo/White</material>
  </gazebo>
  <joint name="bottom_joint" type="fixed">
    <origin rpy="0 0 0" xyz="0 0 0"/>
    <parent link="base_link"/>
    <child link="bottom_link"/>
  </joint>
  <!-- ////  base link -> shoulder link  ////-->
  <link name="base_link">
    <visual>
      <origin rpy="0 0 0" xyz="0 0 0"/>
      <geometry>
        <cylinder length="0.04" radius="0.05"/>
      </geometry>
      <material name="White"/>
    </visual>
    <collision>
      <origin rpy="0 0 0" xyz="0 0 0"/>
      <geometry>
        <cylinder length="0.04" radius="0.05"/>
      </geometry>
    </collision>
    <inertial>
      <mass value="0.1"/>
      <inertia ixx="1.0" ixy="0.0" ixz="0.0" iyy="0.5" iyz="0.0" izz="1.0"/>
    </inertial>
  </link>
  <gazebo reference="base_link">
    <material>Gazebo/White</material>
  </gazebo>
  <joint name="base_joint" type="revolute">
    <parent link="base_link"/>
    <child link="shoulder_link"/>
    <origin rpy="0 0 0" xyz="0 0 0.025"/>
    <axis xyz="0 0 1"/>
    <limit effort="300" lower="-1.570795" upper="1.570795" velocity="1"/>
    <dynamics damping="50" friction="1"/>
  </joint>
  <!-- ////  shoulder link -> elbow link  ////-->
  <link name="shoulder_link">
    <visual>
      <origin rpy="0 0 0" xyz="0 0 0"/>
      <geometry>
        <cylinder length="0.002" radius="0.04"/>
      </geometry>
      <material name="Red"/>
    </visual>
    <collision>
      <origin rpy="0 0 0" xyz="0 0 0"/>
      <geometry>
        <cylinder length="0.002" radius="0.04"/>
      </geometry>
    </collision>
    <inertial>
      <mass value="0.1"/>
      <inertia ixx="1.0" ixy="0.0" ixz="0.0" iyy="0.5" iyz="0.0" izz="1.0"/>
    </inertial>
  </link>
  <gazebo reference="shoulder_link">
    <material>Gazebo/Red</material>
  </gazebo>
  <joint name="shoulder_joint" type="revolute">
    <parent link="shoulder_link"/>
    <child link="elbow_link"/>
    <origin rpy="0 0 0" xyz="0 0 0.006"/>
    <axis xyz="0 -1 0"/>
    <limit effort="300" lower="-1.4835298642" upper="1.4835298642" velocity="1"/>
    <dynamics damping="50" friction="1"/>
  </joint>
  <!-- ////  elbow link -> wrist flex link  ////-->
  <link name="elbow_link">
    <visual>
      <origin rpy="0 0 0" xyz="0 0 0.045"/>
      <geometry>
        <box size="0.015 0.04 0.1"/>
      </geometry>
      <material name="Black"/>
    </visual>
    <collision>
      <origin rpy="0 0 0" xyz="0 0 0.045"/>
      <geometry>
        <box size="0.015 0.04 0.1"/>
      </geometry>
    </collision>
    <inertial>
      <mass value="0.1"/>
      <inertia ixx="1.0" ixy="0.0" ixz="0.0" iyy="0.5" iyz="0.0" izz="1.0"/>
    </inertial>
  </link>
  <gazebo reference="elbow_link">
    <material>Gazebo/Black</material>
  </gazebo>
  <joint name="elbow_joint" type="revolute">
    <parent link="elbow_link"/>
    <child link="wrist_flex_link"/>
    <origin rpy="0 0 0" xyz="0 0 0.09"/>
    <axis xyz="0 1 0"/>
    <limit effort="300" lower="-1.0471975512" upper="1.57079632679" velocity="1"/>
    <dynamics damping="50" friction="1"/>
  </joint>
  <!-- ////  wrist flex link -> wrist rot link  ////-->
  <link name="wrist_flex_link">
    <visual>
      <origin rpy="0 0 0" xyz="0 0 0.045"/>
      <geometry>
        <box size="0.015 0.035 0.1"/>
      </geometry>
      <material name="Red"/>
    </visual>
    <collision>
      <origin rpy="0 0 0" xyz="0 0 0.045"/>
      <geometry>
        <box size="0.015 0.035 0.1"/>
      </geometry>
    </collision>
    <inertial>
      <mass value="0.1"/>
      <inertia ixx="1.0" ixy="0.0" ixz="0.0" iyy="0.5" iyz="0.0" izz="1.0"/>
    </inertial>
  </link>
  <gazebo reference="wrist_flex_link">
    <material>Gazebo/Red</material>
  </gazebo>
  <joint name="wrist_flex_joint" type="revolute">
    <parent link="wrist_flex_link"/>
    <child link="wrist_rot_link"/>
    <origin rpy="0 0 0" xyz="0 0 0.09"/>
    <axis xyz="0 1 0"/>
    <limit effort="300" lower="-1.570795" upper="0" velocity="1"/>
    <dynamics damping="50" friction="1"/>
  </joint>
  <!-- ////  wrist rot link -> gripper link  ////-->
  <link name="wrist_rot_link">
    <visual>
      <origin rpy="0 0 0" xyz="0.01 0 0.01"/>
      <geometry>
        <box size="0.025 0.025 0.025"/>
      </geometry>
      <material name="Black"/>
    </visual>
    <collision>
      <origin rpy="0 0 0" xyz="0.01 0 0.01"/>
      <geometry>
        <box size="0.025 0.025 0.025"/>
      </geometry>
    </collision>
    <inertial>
      <mass value="0.1"/>
      <inertia ixx="1.0" ixy="0.0" ixz="0.0" iyy="0.5" iyz="0.0" izz="1.0"/>
    </inertial>
  </link>
  <gazebo reference="wrist_rot_link">
    <material>Gazebo/Black</material>
  </gazebo>
  <joint name="camera_mast_joint" type="fixed">
    <origin rpy="0 0 0" xyz="0 0.2 0"/>
    <parent link="bottom_link"/>
    <child link="camera_mast_link"/>
  </joint>
  <link name="camera_mast_link">
    <visual>
      <origin rpy="0 0 0" xyz="0 0 0.155"/>
      <geometry>
        <box size="0.01 0.01 0.35"/>
      </geometry>
      <material name="Gray"/>
    </visual>
    <collision>
      <origin rpy="0 0 0" xyz=" 0 0 0.155"/>
      <geometry>
        <box size="0.01 0.01 0.35"/>
      </geometry>
    </collision>
  </link>
  <joint name="camera_mast_joint_2" type="fixed">
    <origin rpy="0 0 0" xyz="0 0 0.25"/>
    <parent link="camera_mast_link"/>
    <child link="camera_mast_link_2"/>
  </joint>
  <link name="camera_mast_link_2">
    <visual>
      <origin rpy="0 0 0" xyz="-0.07 0 0"/>
      <geometry>
        <box size="0.15 0.01 0.01"/>
      </geometry>
      <material name="Gray"/>
    </visual>
    <collision>
      <origin rpy="0 0 0" xyz="-0.07 0 0"/>
      <geometry>
        <box size="0.15 0.01 0.01"/>
      </geometry>
    </collision>
  </link>
  <joint name="camera_joint" type="fixed">
    <origin rpy="0 1.0471975512 -1.57079632679" xyz="-0.14 0 -0.005"/>
    <parent link="camera_mast_link_2"/>
    <child link="camera_link"/>
  </joint>
  <!-- Camera -->
  <link name="camera_link">
    <collision>
      <origin rpy="0 0 0" xyz="0 0 -0.005"/>
      <geometry>
        <box size="0.01 0.01 0.01"/>
      </geometry>
    </collision>
    <visual>
      <origin rpy="0 0 0" xyz="0 0 -0.005"/>
      <geometry>
        <box size="0.01 0.01 0.01"/>
      </geometry>
      <material name="Red"/>
    </visual>
    <inertial>
      <mass value="1e-5"/>
      <origin rpy="0 0 0" xyz="0 0 0"/>
      <inertia ixx="1e-6" ixy="0" ixz="0" iyy="1e-6" iyz="0" izz="1e-6"/>
    </inertial>
  </link>
  <!--joint name="camera_optical_joint" type="fixed">
        <origin xyz="0 0 0" rpy="0 0 0"/>
        <parent link="camera_link"/>
        <child link="camera_optical_link"/>
    </joint>

    <link name="camera_optical_link">
        <inertial>
            <mass value="1e-5"/>
            <origin xyz="0 0 0" rpy="${90*deg_to_rad} ${90*deg_to_rad} ${90*deg_to_rad}"/>
            <inertia ixx="1e-6" ixy="0" ixz="0" iyy="1e-6" iyz="0" izz="1e-6"/>
        </inertial>
    </link-->
  <!-- camera -->
  <gazebo reference="camera_link">
    <material>Gazebo/Red</material>
    <sensor name="camera1" type="camera">
      <update_rate>30.0</update_rate>
      <camera name="head">
        <!-- 50-degree FOV  = 0.873-->
        <horizontal_fov>1.3962634</horizontal_fov>
        <image>
          <width>640</width>
          <height>480</height>
          <format>R8G8B8</format>
        </image>
        <clip>
          <near>0.02</near>
          <far>300</far>
        </clip>
        <noise>
          <type>gaussian</type>
          <mean>0.0</mean>
          <stddev>0.007</stddev>
        </noise>
      </camera>
      <plugin filename="libgazebo_ros_camera.so" name="camera_sensor">
        <alwaysOn>true</alwaysOn>
        <updateRate>0.0</updateRate>
        <cameraName>camera</cameraName>
        <imageTopicName>image_raw</imageTopicName>
        <cameraInfoTopicName>camera_info</cameraInfoTopicName>
        <frameName>camera_link</frameName>
        <hackBaseline>0.07</hackBaseline>
        <distortionK1>0.0</distortionK1>
        <distortionK2>0.0</distortionK2>
        <distortionK3>0.0</distortionK3>
        <distortionT1>0.0</distortionT1>
        <distortionT2>0.0</distortionT2>
      </plugin>
    </sensor>
  </gazebo>
  <joint name="camera_mast_joint_y" type="fixed">
    <origin rpy="0 0 0" xyz="0 -0.2 0"/>
    <parent link="bottom_link"/>
    <child link="camera_mast_link_y"/>
  </joint>
  <link name="camera_mast_link_y">
    <visual>
      <origin rpy="0 0 0" xyz="0 0 0.155"/>
      <geometry>
        <box size="0.01 0.01 0.35"/>
      </geometry>
      <material name="Gray"/>
    </visual>
    <collision>
      <origin rpy="0 0 0" xyz=" 0 0 0.155"/>
      <geometry>
        <box size="0.01 0.01 0.35"/>
      </geometry>
    </collision>
  </link>
  <joint name="camera_mast_joint_y_2" type="fixed">
    <origin rpy="0 0 0" xyz="0 0 0.25"/>
    <parent link="camera_mast_link_y"/>
    <child link="camera_mast_link_y_2"/>
  </joint>
  <link name="camera_mast_link_y_2">
    <visual>
      <origin rpy="0 0 0" xyz="-0.07 0 0"/>
      <geometry>
        <box size="0.15 0.01 0.01"/>
      </geometry>
      <material name="Gray"/>
    </visual>
    <collision>
      <origin rpy="0 0 0" xyz="-0.07 0 0"/>
      <geometry>
        <box size="0.15 0.01 0.01"/>
      </geometry>
    </collision>
  </link>
  <joint name="camera_joint_y" type="fixed">
    <origin rpy="0 1.0471975512 1.57079632679" xyz="-0.14 0 -0.005"/>
    <parent link="camera_mast_link_y_2"/>
    <child link="camera_link_y"/>
  </joint>
  <!-- Camera -->
  <link name="camera_link_y">
    <collision>
      <origin rpy="0 0 0" xyz="0 0 -0.005"/>
      <geometry>
        <box size="0.01 0.01 0.01"/>
      </geometry>
    </collision>
    <visual>
      <origin rpy="0 0 0" xyz="0 0 -0.005"/>
      <geometry>
        <box size="0.01 0.01 0.01"/>
      </geometry>
      <material name="Red"/>
    </visual>
    <inertial>
      <mass value="1e-5"/>
      <origin rpy="0 0 0" xyz="0 0 0"/>
      <inertia ixx="1e-6" ixy="0" ixz="0" iyy="1e-6" iyz="0" izz="1e-6"/>
    </inertial>
  </link>
  <!-- camera -->
  <gazebo reference="camera_link_y">
    <material>Gazebo/Red</material>
    <sensor name="camera2" type="camera">
      <update_rate>30.0</update_rate>
      <camera name="head">
        <!-- 50-degree FOV  = 0.873-->
        <horizontal_fov>1.3962634</horizontal_fov>
        <image>
          <width>640</width>
          <height>480</height>
          <format>R8G8B8</format>
        </image>
        <clip>
          <near>0.02</near>
          <far>300</far>
        </clip>
        <noise>
          <type>gaussian</type>
          <mean>0.0</mean>
          <stddev>0.007</stddev>
        </noise>
      </camera>
      <plugin filename="libgazebo_ros_camera.so" name="camera_sensor">
        <alwaysOn>true</alwaysOn>
        <updateRate>0.0</updateRate>
        <cameraName>camera_y</cameraName>
        <imageTopicName>image_raw</imageTopicName>
        <cameraInfoTopicName>camera_info</cameraInfoTopicName>
        <frameName>camera_link_y</frameName>
        <hackBaseline>0.07</hackBaseline>
        <distortionK1>0.0</distortionK1>
        <distortionK2>0.0</distortionK2>
        <distortionK3>0.0</distortionK3>
        <distortionT1>0.0</distortionT1>
        <distortionT2>0.0</distortionT2>
      </plugin>
    </sensor>
  </gazebo>
  <!-- ////  bottom link -> sink bottom link  ////-->
  <joint name="sink_bottom_joint" type="fixed">
    <origin rpy="0 0 0" xyz="-0.17 0 0"/>
    <parent link="bottom_link"/>
    <child link="sink_bottom_link"/>
  </joint>
  <link name="sink_bottom_link">
    <visual>
      <origin rpy="0 0 0" xyz="0 0 -0.01"/>
      <geometry>
        <box size="0.2 0.2 0.02"/>
      </geometry>
      <material name="Black"/>
    </visual>
    <collision>
      <origin rpy="0 0 0" xyz="0 0 -0.01"/>
      <geometry>
        <box size="0.2 0.2 0.02"/>
      </geometry>
    </collision>
  </link>
  <gazebo reference="sink_bottom_link">
    <material>Gazebo/Black</material>
  </gazebo>
  <!-- //// sink bottom link -> sink wall left link  ////-->
  <joint name="sink_wall_left_joint" type="fixed">
    <origin rpy="0 0 0" xyz="0 -0.0975 0"/>
    <parent link="sink_bottom_link"/>
    <child link="sink_wall_left"/>
  </joint>
  <link name="sink_wall_left">
    <visual>
      <origin rpy="0 0 0" xyz="0 0 0.0125"/>
      <geometry>
        <box size="0.2 0.005 0.025"/>
      </geometry>
      <material name="Gray"/>
    </visual>
    <collision>
      <origin rpy="0 0 0" xyz="0 0 0.0125"/>
      <geometry>
        <box size="0.2 0.005 0.025"/>
      </geometry>
    </collision>
  </link>
  <!-- //// sink bottom link -> sink wall right link  ////-->
  <joint name="sink_wall_right_joint" type="fixed">
    <origin rpy="0 0 0" xyz="0 0.0975 0"/>
    <parent link="sink_bottom_link"/>
    <child link="sink_wall_right"/>
  </joint>
  <link name="sink_wall_right">
    <visual>
      <origin rpy="0 0 0" xyz="0 0 0.0125"/>
      <geometry>
        <box size="0.2 0.005 0.025"/>
      </geometry>
      <material name="Gray"/>
    </visual>
    <collision>
      <origin rpy="0 0 0" xyz="0 0 0.0125"/>
      <geometry>
        <box size="0.2 0.005 0.025"/>
      </geometry>
    </collision>
  </link>
  <!-- //// sink bottom link -> sink wall up link  ////-->
  <joint name="sink_wall_up_joint" type="fixed">
    <origin rpy="0 0 0" xyz="-0.0975 0 0"/>
    <parent link="sink_bottom_link"/>
    <child link="sink_wall_up"/>
  </joint>
  <link name="sink_wall_up">
    <visual>
      <origin rpy="0 0 0" xyz="0 0 0.0125"/>
      <geometry>
        <box size="0.005 0.2 0.025"/>
      </geometry>
      <material name="Gray"/>
    </visual>
    <collision>
      <origin rpy="0 0 0" xyz="0 0 0.0125"/>
      <geometry>
        <box size="0.005 0.2 0.025"/>
      </geometry>
    </collision>
  </link>
  <!-- //// sink bottom link -> sink wall down link  ////-->
  <joint name="sink_wall_down_joint" type="fixed">
    <origin rpy="0 0 0" xyz="0.0975 0 0"/>
    <parent link="sink_bottom_link"/>
    <child link="sink_wall_down"/>
  </joint>
  <link name="sink_wall_down">
    <visual>
      <origin rpy="0 0 0" xyz="0 0 0.0125"/>
      <geometry>
        <box size="0.005 0.2 0.025"/>
      </geometry>
      <material name="Gray"/>
    </visual>
    <collision>
      <origin rpy="0 0 0" xyz="0 0 0.0125"/>
      <geometry>
        <box size="0.005 0.2 0.025"/>
      </geometry>
    </collision>
  </link>
  <joint name="wrist_rot_joint" type="revolute">
    <parent link="wrist_rot_link"/>
    <child link="gripper_bottom_link"/>
    <origin rpy="0 0 0" xyz="0.02 0.008 0.0225"/>
    <axis xyz="0 0 1"/>
    <limit effort="300" lower="-1.570795" upper="0" velocity="1"/>
    <dynamics damping="50" friction="1"/>
  </joint>
  <!-- ////  wrist rot link -> gripper bottom link  ////-->
  <link name="gripper_bottom_link">
    <visual>
      <origin rpy="0 0 0" xyz="0 0 0.005"/>
      <geometry>
        <box size="0.003 0.01 0.01"/>
      </geometry>
      <material name="Red"/>
    </visual>
    <collision>
      <origin rpy="0 0 0" xyz="0 0 0.005"/>
      <geometry>
        <box size="0.003 0.01 0.01"/>
      </geometry>
    </collision>
    <inertial>
      <mass value="0.1"/>
      <inertia ixx="1.0" ixy="0.0" ixz="0.0" iyy="0.5" iyz="0.0" izz="1.0"/>
    </inertial>
  </link>
  <gazebo reference="gripper_bottom_link">
    <material>Gazebo/Red</material>
  </gazebo>
  <joint name="gripper_attach_joint" type="fixed">
    <parent link="gripper_bottom_link"/>
    <child link="gripper_link"/>
    <origin rpy="0 0 0" xyz="0 0 0.01"/>
  </joint>
  <!-- ////  gripper link  ////-->
  <link name="gripper_link">
    <visual>
      <origin rpy="0 0 0" xyz="0 0 0.002"/>
      <geometry>
        <box size="0.01 0.035 0.004"/>
      </geometry>
      <material name="Red"/>
    </visual>
    <collision>
      <origin rpy="0 0 0" xyz="0 0 0.002"/>
      <geometry>
        <box size="0.01 0.035 0.004"/>
      </geometry>
    </collision>
    <inertial>
      <mass value="0.1"/>
      <inertia ixx="1.0" ixy="0.0" ixz="0.0" iyy="0.5" iyz="0.0" izz="1.0"/>
    </inertial>
  </link>
  <gazebo reference="gripper_link">
    <material>Gazebo/Red</material>
  </gazebo>
  <!-- ////  gripper link -> gripper finger link1  ////-->
  <joint name="finger_joint1" type="prismatic">
    <parent link="gripper_link"/>
    <child link="gripper_finger_link1"/>
    <origin xyz="0 0 0.002"/>
    <axis xyz="0 1 0"/>
    <limit effort="200" lower="-0.015" upper="0" velocity="1.0"/>
    <dynamics damping="50" friction="1"/>
  </joint>
  <link name="gripper_finger_link1">
    <visual>
      <origin xyz="0 0.016 0.03"/>
      <geometry>
        <box size="0.01 0.002 0.06"/>
      </geometry>
      <material name="Black"/>
    </visual>
    <collision>
      <origin xyz="0 0.016 0.03"/>
      <geometry>
        <box size="0.01 0.002 0.06"/>
      </geometry>
    </collision>
    <inertial>
      <mass value="0.1"/>
      <inertia ixx="1.0" ixy="0.0" ixz="0.0" iyy="0.5" iyz="0.0" izz="1.0"/>
    </inertial>
  </link>
  <gazebo reference="l_gripper_aft_link">
    <material>Gazebo/Black</material>
  </gazebo>
  <!-- ////  gripper link -> gripper finger link2  ////-->
  <joint name="finger_joint2" type="prismatic">
    <parent link="gripper_link"/>
    <child link="gripper_finger_link2"/>
    <origin xyz="0 0 0.002"/>
    <axis xyz="0 1 0"/>
    <limit effort="200" lower="0" upper="0.015" velocity="1.0"/>
    <dynamics damping="50" friction="1"/>
  </joint>
  <link name="gripper_finger_link2">
    <visual>
      <origin xyz="0 -0.016 0.03"/>
      <geometry>
        <box size="0.01 0.002 0.06"/>
      </geometry>
      <material name="Black"/>
    </visual>
    <collision>
      <origin xyz="0 -0.016 0.03"/>
      <geometry>
        <box size="0.01 0.002 0.06"/>
      </geometry>
    </collision>
    <inertial>
      <mass value="0.1"/>
      <inertia ixx="1.0" ixy="0.0" ixz="0.0" iyy="0.5" iyz="0.0" izz="1.0"/>
    </inertial>
  </link>
  <gazebo reference="r_gripper_aft_link">
    <material>Gazebo/Black</material>
  </gazebo>
  <!-- ////  gripper link -> grasp frame link  ////-->
  <link name="grasp_frame_link">
    <inertial>
      <origin rpy="0 0 0" xyz="0 0 0"/>
      <mass value="0.0001"/>
      <cuboid_inertia mass="0.0001" x="0.001" y="0.001" z="0.001"/>
      <inertia ixx="1.0" ixy="0.0" ixz="0.0" iyy="10.0" iyz="0.0" izz="1.0"/>
    </inertial>
    <!--visual>
            <origin xyz="0 0 0"/>
            <geometry>
                <box size="0.01 0.01 0.01"/>
            </geometry>
            <material name="White"/>
        </visual-->
  </link>
  <joint name="grasp_frame_joint" type="fixed">
    <parent link="gripper_link"/>
    <child link="grasp_frame_link"/>
    <origin rpy="0 0 0" xyz="0 0 0.065"/>
    <!--limit effort="300" velocity="1" lower="0" upper="0"/-->
  </joint>
  <!-- transmission block -->
  <transmission name="tran1">
    <type>transmission_interface/SimpleTransmission</type>
    <joint name="base_joint">
      <hardwareInterface>PositionJointInterface</hardwareInterface>
    </joint>
    <actuator name="motor1">
      <hardwareInterface>PositionJointInterface</hardwareInterface>
      <mechanicalReduction>1</mechanicalReduction>
    </actuator>
  </transmission>
  <transmission name="tran1">
    <type>transmission_interface/SimpleTransmission</type>
    <joint name="shoulder_joint">
      <hardwareInterface>PositionJointInterface</hardwareInterface>
    </joint>
    <actuator name="motor1">
      <hardwareInterface>PositionJointInterface</hardwareInterface>
      <mechanicalReduction>1</mechanicalReduction>
    </actuator>
  </transmission>
  <transmission name="tran1">
    <type>transmission_interface/SimpleTransmission</type>
    <joint name="elbow_joint">
      <hardwareInterface>PositionJointInterface</hardwareInterface>
    </joint>
    <actuator name="motor1">
      <hardwareInterface>PositionJointInterface</hardwareInterface>
      <mechanicalReduction>1</mechanicalReduction>
    </actuator>
  </transmission>
  <transmission name="tran1">
    <type>transmission_interface/SimpleTransmission</type>
    <joint name="wrist_flex_joint">
      <hardwareInterface>PositionJointInterface</hardwareInterface>
    </joint>
    <actuator name="motor1">
      <hardwareInterface>PositionJointInterface</hardwareInterface>
      <mechanicalReduction>1</mechanicalReduction>
    </actuator>
  </transmission>
  <transmission name="tran1">
    <type>transmission_interface/SimpleTransmission</type>
    <joint name="wrist_rot_joint">
      <hardwareInterface>PositionJointInterface</hardwareInterface>
    </joint>
    <actuator name="motor1">
      <hardwareInterface>PositionJointInterface</hardwareInterface>
      <mechanicalReduction>1</mechanicalReduction>
    </actuator>
  </transmission>
  <transmission name="tran1">
    <type>transmission_interface/SimpleTransmission</type>
    <joint name="finger_joint1">
      <hardwareInterface>PositionJointInterface</hardwareInterface>
    </joint>
    <actuator name="motor1">
      <hardwareInterface>PositionJointInterface</hardwareInterface>
      <mechanicalReduction>1</mechanicalReduction>
    </actuator>
  </transmission>
  <transmission name="tran1">
    <type>transmission_interface/SimpleTransmission</type>
    <joint name="finger_joint2">
      <hardwareInterface>PositionJointInterface</hardwareInterface>
    </joint>
    <actuator name="motor1">
      <hardwareInterface>PositionJointInterface</hardwareInterface>
      <mechanicalReduction>1</mechanicalReduction>
    </actuator>
  </transmission>
  <xacro:base name="base"/>
  <xacro:arm parent="base"/>
  <xacro:gripper parent="tool"/>
  <!-- ros_control plugin -->
  <gazebo>
    <plugin filename="libgazebo_ros_control.so" name="gazebo_ros_control">
      <robotNamespace>/as_arm</robotNamespace>
    </plugin>
  </gazebo>
</robot>
